<?xml version="1.0"?>
<robot name="LWR" xmlns:xacro="http://www.ros.org/wiki/xacro">

  <xacro:include filename="$(find lwr_description)/urdf/util_defs.xml"/>
  <xacro:include filename="$(find lwr_description)/urdf/common.xacro"/>
  



  <property name="arm_elem_base_mass" value="2.0"/>
  <property name="arm_elem_link_mass" value="2.0"/>
  <property name="arm_elem_ball_link_mass" value="2.0"/>
  <property name="arm_elem_end_link_mass" value="2.0"/>
  <property name="safety_controller_k_pos" value="100" />
  <property name="safety_controller_k_vel" value="2" />
  <property name="joint_damping" value="2" /> <!-- It needs to be very high .. 40, 20-->
  <property name="joint_friction" value="0.1" /> <!-- Not sure if that is used, apparently not ... 0.8? -->
  <property name="arm_velocity_scale_factor" value="1"/> <!-- Not sure about that ... -->
  <property name="mesh_path" value = "package://lwr_description/meshes" />

<xacro:macro name="xtransmission" params="name id">
	<transmission name="${name}_arm_${id}_trans">
		<type>transmission_interface/SimpleTransmission</type>
       		<joint name="${name}_arm_${id}_joint">
            		<hardwareInterface>EffortJointInterface</hardwareInterface>
        	</joint>
        	<actuator name="${name}_motor_${id}">
            		<mechanicalReduction>1</mechanicalReduction>
        	</actuator>
	</transmission>
</xacro:macro>


<!-- right is either 1 (for right arm) or -1 (for left arm) -->
<xacro:macro name="kuka_lwr_arm" params="parent name right tool_name">

<!-- JOINT BASE -->
<joint name="${parent}_${name}_arm_base_joint" type="fixed">
	<origin xyz="0 0 0" rpy="0 0 0"/>
	<parent link="${parent}"/>
	<child link="${name}_arm_base_link"/>
</joint>

<!-- LINK BASE -->
<link name="${name}_arm_base_link">

        <visual>
          	<origin xyz="0 0 0" rpy="0 0 0"/>
          	<geometry>
            		<mesh filename="${mesh_path}/meshes_arm/arm_base.dae"/>
          	</geometry>
          	<material name="Orange"/>
        </visual>
        
	<collision>
		<origin xyz="0 0 0" rpy="0 0 0"/>
          	<geometry>
            		<mesh filename="${mesh_path}/meshes_arm/convex/arm_base_convex.stl"/>
          	</geometry>
        </collision>
 </link>


<!-- JOINT ARM 0 -->
<joint name="${name}_arm_0_joint" type="revolute">
        <origin xyz="0 0 0.11" rpy="0 0 0"/>
        <axis xyz="0 0 1"/>
        <limit lower="${-170 * M_PI / 180}" 
	       upper="${170 * M_PI / 180}"
              effort="204" 
	    velocity="${arm_velocity_scale_factor * 110 * M_PI / 180}" 
	/>
       <dynamics damping="${joint_damping}" friction="${joint_friction}"/>
       <parent link="${name}_arm_base_link"/>
       <child link="${name}_arm_1_link"/>
</joint>


<!-- LINK ARM 1 -->
<link name="${name}_arm_1_link">

	<visual>
		<origin xyz="0 0 0" rpy="0 0 ${M_PI}"/>
		<geometry>
	        	<mesh filename="${mesh_path}/meshes_arm/arm_segment_a.dae"/>
            	</geometry>
            	<material name="Orange"/>
        </visual>

        <collision>
            <origin xyz="0 0 0" rpy="0 0 ${M_PI}"/>
            <geometry>
              <mesh filename="${mesh_path}/meshes_arm/convex/arm_segment_a_convex.stl"/>
            </geometry>
          </collision>
</link>

<!-- JOINT ARM 1 -->
<joint name="${name}_arm_1_joint" type="revolute">
	<origin xyz="0 0 0.20" rpy="0 0 0"/>
		<axis xyz="0 -1 0"/>
        <limit lower="${-90 * M_PI / 180}" upper="${90 * M_PI / 180}" effort="306" velocity="${arm_velocity_scale_factor * 110 * M_PI / 180}" />       
        <safety_controller 
	     soft_lower_limit="${-118 * M_PI / 180}"
             soft_upper_limit="${118 * M_PI / 180}"
             k_position="${safety_controller_k_pos}"
             k_velocity="${safety_controller_k_vel}"/>
        <dynamics damping="${joint_damping}" friction="${joint_friction}"/>
        <parent link="${name}_arm_1_link"/>
        <child link="${name}_arm_2_link"/>
</joint>






<!-- LINK ARM 2 -->
<link name="${name}_arm_2_link">

        <visual>
         	<origin xyz="0 0 0.2" rpy="${M_PI} 0 ${M_PI}"/>
          	<geometry>
            		<mesh filename="${mesh_path}/meshes_arm/arm_segment_b.dae"/>
          	</geometry>
          	<material name="Orange"/>
        </visual>

        <collision>
        	<origin xyz="0 0 0.2" rpy="${M_PI} 0 ${M_PI}"/>
          	<geometry>
            		<mesh filename="${mesh_path}/meshes_arm/convex/arm_segment_b_convex.stl"/>
          	</geometry>
        </collision>
</link>

<!-- JOINT ARM 2 -->
<joint name="${name}_arm_2_joint" type="revolute">
	<origin xyz="0 0 0.20" rpy="0 0 0"/>
        <axis xyz="0 0 1"/>
        <limit lower="${-170 * M_PI / 180}" upper="${170 * M_PI / 180}" effort="204" velocity="${arm_velocity_scale_factor * 130 * M_PI / 180}" />
        	<dynamics damping="${joint_damping}" friction="${joint_friction}"/>
                <parent link="${name}_arm_2_link"/>
                <child link="${name}_arm_3_link"/>
</joint>







<!-- LINK ARM 3 -->
<link name="${name}_arm_3_link">
	
	<visual>
		<origin xyz="0 0 0" rpy="0 0 0"/>
                <geometry>
        	        <mesh filename="${mesh_path}/meshes_arm/arm_segment_a.dae"/>
                </geometry>
                <material name="Orange"/>
        </visual>

        <collision>
	        <origin xyz="0 0 0" rpy="0 0 0"/>
                <geometry>
	                <mesh filename="${mesh_path}/meshes_arm/convex/arm_segment_a_convex.stl"/>
	        </geometry>
       </collision>
</link>

<!-- JOINT ARM 3 --> 
<joint name="${name}_arm_3_joint" type="revolute">
 	<origin xyz="0 0 0.20" rpy="0 0 0"/>
 	<axis xyz="0 1 0"/>
	<limit lower="${-120 * M_PI / 180}" upper="${120 * M_PI / 180}" effort="306" velocity="${arm_velocity_scale_factor * 130 * M_PI / 180}" />
	<safety_controller soft_lower_limit="${-118 * M_PI / 180}"
         soft_upper_limit="${118 * M_PI / 180}"
         k_position="${safety_controller_k_pos}"
         k_velocity="${safety_controller_k_vel}"/>
         <dynamics damping="${joint_damping}" friction="${joint_friction}"/>
         <parent link="${name}_arm_3_link"/>
         <child link="${name}_arm_4_link"/>
</joint>








<!-- LINK ARM 4 -->
<link name="${name}_arm_4_link">

	 <visual>
	 	<origin xyz="0 0 0.2" rpy="0 ${M_PI} ${M_PI}"/>
		<geometry>
              		<mesh filename="${mesh_path}/meshes_arm/arm_segment_b.dae"/>
            	</geometry>
            	<material name="Orange"/>
          </visual>

          <collision>
            	<origin xyz="0 0 0.2" rpy="0 ${M_PI} ${M_PI}"/>
            	<geometry>
              		<mesh filename="${mesh_path}/meshes_arm/convex/arm_segment_b_convex.stl"/>
            	</geometry>
          </collision>
</link>

<!-- JOINT ARM 4 -->
<joint name="${name}_arm_4_joint" type="revolute">
	<origin xyz="0 0 0.20" rpy="0 0 0"/>
        <axis xyz="0 0 1"/>
        <limit lower="${-170 * M_PI / 180}" upper="${170 * M_PI / 180}" effort="204" velocity="${arm_velocity_scale_factor * 130 * M_PI / 180}" />
        <safety_controller soft_lower_limit="${-168 * M_PI / 180}"
             soft_upper_limit="${168 * M_PI / 180}"
             k_position="${safety_controller_k_pos}"
             k_velocity="${safety_controller_k_vel}"/>
             <dynamics damping="${joint_damping}" friction="${joint_friction}"/>
             <parent link="${name}_arm_4_link"/>
             <child link="${name}_arm_5_link"/>
</joint>



<!-- LINK ARM 5 -->
<link name="${name}_arm_5_link">

	<visual>
		<origin xyz="0 0 0" rpy="0 0 ${M_PI}"/>
		<geometry name="${name}_arm_5_geom">
			<mesh filename="${mesh_path}/meshes_arm/arm_segment_last.dae"/>
                </geometry>
                <material name="Orange"/>
        </visual>

        <collision>
		<origin xyz="0 0 0" rpy="0 0 ${M_PI}"/>
                <geometry>
                  <mesh filename="${mesh_path}/meshes_arm/convex/arm_segment_last_convex.stl"/>
                </geometry>
        </collision>
</link>

<!-- JOINT ARM 5 -->
<joint name="${name}_arm_5_joint" type="revolute">
	<origin xyz="0 0 0.19" rpy="0 0 0"/>
        <axis xyz="0 -1 0"/>
        <limit lower="${-120 * M_PI / 180}" upper="${120 * M_PI / 180}" effort="306" velocity="${arm_velocity_scale_factor * 180 * M_PI / 180}" />
       	<safety_controller soft_lower_limit="${-118 * M_PI / 180}"
                 soft_upper_limit="${118 * M_PI / 180}"
                 k_position="${safety_controller_k_pos}"
                 k_velocity="${safety_controller_k_vel}"/>
                 <dynamics damping="${joint_damping}" friction="${joint_friction}"/>
                 <parent link="${name}_arm_5_link"/>
                 <child link="${name}_arm_6_link"/>
</joint>






<!-- LINK ARM 6 -->
<link name="${name}_arm_6_link">

        <visual>
 		<origin xyz="0 0 0" rpy="0 0 ${M_PI}"/>
 		<geometry>
 	         	<mesh filename="${mesh_path}/meshes_arm/arm_wrist.dae"/>
                </geometry>
                <material name="Grey"/>
        </visual>

        <collision>
		<origin xyz="0 0 0" rpy="0 0 ${M_PI}"/>
                <geometry>
			<mesh filename="${mesh_path}/meshes_arm/convex/arm_wrist_convex.stl"/>
                </geometry>
        </collision>
</link>

<!-- JOINT ARM 6 -->
<joint name="${name}_arm_6_joint" type="revolute">
	<origin xyz="0 0 0.078" rpy="0 0 0"/>
        <axis xyz="0 0 1"/>
        <limit lower="${-170 * M_PI / 180}" upper="${170 * M_PI / 180}" effort="204" velocity="${arm_velocity_scale_factor * 180 * M_PI / 180}" />
                   <safety_controller soft_lower_limit="${-168 * M_PI / 180}"
                   soft_upper_limit="${168 * M_PI / 180}"
                   k_position="${safety_controller_k_pos}"
                   k_velocity="${safety_controller_k_vel}"/>
                   <dynamics damping="${joint_damping}" friction="${joint_friction}"/>
                   <parent link="${name}_arm_6_link"/>
                   <child link="${name}_arm_7_link"/>
</joint>








<!-- LINK ARM 7 -->
<link name="${name}_arm_7_link">
         
	<visual>
          	<origin xyz="0 0 0" rpy="0 0 ${right * -1/4 * M_PI  +  M_PI}"/>
                <geometry>
                	<mesh filename="${mesh_path}/meshes_arm/arm_flanche${tool_name}.dae"/>
                 </geometry>
                 <material name="Grey"/>                
	</visual>
        
	<collision>
		<origin xyz="0 0 0" rpy="0 0 ${right * -1/4 * M_PI  +  M_PI}"/>
                <geometry>
	                <mesh filename="${mesh_path}/meshes_arm/convex/arm_flanche${tool_name}_convex.stl"/>
	        </geometry>
        </collision>
</link>


<!-- LINK HAND 
<link name="lwr_arm_hand_link" />

<joint name="${name}_arm_hand_fixed_joint" type="fixed">
	<origin xyz="${-right * 0.075} -0.075 -0.094" rpy="${0.5*right*M_PI} 0 ${(1.5 + 0.25*right)*M_PI}"/>
    	<parent link="${name}_arm_7_link"/>
   	<child link="${name}_arm_hand_link"/>
</joint>
-->
<!-- TRANSMISSIONS -->


<xacro:xtransmission name="${name}" id="0"/>
<xacro:xtransmission name="${name}" id="1"/>
<xacro:xtransmission name="${name}" id="2"/>
<xacro:xtransmission name="${name}" id="3"/>
<xacro:xtransmission name="${name}" id="4"/>
<xacro:xtransmission name="${name}" id="5"/>
<xacro:xtransmission name="${name}" id="6"/>



</xacro:macro>

</robot>
